Workbook
Name Base_Texts: '[1] SMS Text Volume Cost'!$D$15
Name Case_Rows: #REF!
Name D365_Est_Users: '[2]Dynamics 365'!$D$16
Name Hosting_Options: #REF!
Name Legal_Name_of_Respondent: '[3]1 - Total Price Summary'!$B$7
Name Respondent_Name: '[4]Phase 1 - Transition Services'!#REF!
Name Sol_Title: '[2]Transition Written Del.& Svcs.'!$C$8
Name Start_Date: '[3]1 - Total Price Summary'!$B$8
Name Transition_Period_Months: '[4]Arkansas Transition Cost'!$E$9
Name YR4ID: '[2]Supplemental Services'!$H$14

Sheet 0. Cover Sheet
B5: EXHIBIT J.6 - Cost Workbook
A7: Solicitation Number: | B7: 696-IT-25-O053
A8: Solicitation Name/Title: | B8: Texas Department of Criminal Justice Corrections Information Technology System 2.0 (CITS 2.0)
A9: Respondent Name: | B9: Respondent Name

Sheet 1. TOC & Instructions
B1: ='0. Cover Sheet'!B5 -> EXHIBIT J.6 - Cost Workbook
A3: Solicitation Number: | B3: ='0. Cover Sheet'!B7 -> 696-IT-25-O053
A4: Solicitation Name/Title: | B4: ='0. Cover Sheet'!B8 -> Texas Department of Criminal Justice Corrections Information Technology System 2.0 (CITS 2.0)
A5: Respondent Name: | B5: ='0. Cover Sheet'!B9 -> Respondent Name
A7: Note: | B7: All editable cells in this worksheet are highlighted in light yellow.
A8: 1 | B8: The Department will not be billed separately for travel costs. Price shall incorporate any travel and lodging considerations necessary for the successful completion of the project.
A9: 2 | B9: Allowable Costs: The Response shall include only costs that are reasonable, necessary, and allowable under State Statutes, Department Policy, and Federal Cost Standards. The Department shall make the final decision on the allowance or acceptability of costs.
A10: 3 | B10: Non-Allowable Costs: The Response shall not include costs that are not allowed by the State or any authorized agency, statute, policy, or procedure. Types of non-allowable costs may include, but are not limited to, alcoholic beverages, bad debts, fundraising, political lobbying, and tobacco products.
A12: Worksheet Title/Hyperlink | B12: Description | C12: Instructions
A13: 0. Cover Sheet | B13: Cover Page | C13: Exhibit J.6 Cost Workbook contains a series of separate spreadsheets designed to provide a robust understanding of the costing model. It is essential that this workbook be completed as part of the RFO response. Respondents must enter the name of their organization in cell B9. No other editing will be allowed on this Cover Page.
A14: Table of Contents
A15: 1 Table of Contents (TOC) & Instructions | B15: Outlines the description of the Cost Workbook worksheets and its high-level content | C15: The worksheets in this Cost Workbook are protected to minimize the risk of compromising the integrity of the workbook structure and formulas. As such, the editable cells within each worksheet are indicated in light yellow highlight as shown in the note below.
A16: Pricing Summary
A17: 2. Total Price Summary | B17: Summary of four-year recurring pricing and one-time costs for Respondent Deliverables | C17: Data in this tab derives from other tabs and requires no input or editing. This tab represents the total costs to the Department for the potential four-year period of performance.
A18: Deliverable Costs
A19: 3. Deliverable Costs | B19: Deliverables Costs (e.g., Development & Implementation) | C19: This worksheet lists all Deliverables specified in Exhibit J.3, Service Requirements, Tab 3. Respondent Deliverables (also listed in Section C.5.4, Required Deliverables). Respondent must enter fixed pricing for the level of effort required to complete each deliverable. Refer to Section F.1, Period of Performance, for expectations related to the required timeframes, not to exceed four years.
A20: Recurring Costs
A21: 4. License/Subscription Costs | B21: Recurring Solution License/Subscription Costs (Monthly) | C21: Respondent must provide license/subscription costs per month for the Solution components for the months in which license subscription costs apply. Cost evaluation will be calculated based on current number of users and the listed per-user subscription cost provided by the Respondent.
A22: 5. Maint. & Operations Costs | B22: Recurring Maintenance and Operations (M&O) Support Costs (Monthly) | C22: Respondent must provide maintenance and operations (M&O) support costs for the Solution throughout the Contract Term. The worksheet is structured to capture monthly costs by year for ongoing maintenance and support.
A23: Infrastructure Costs
A24: 6. Infrastructure | B24: Infrastructure requirements to assist the Department in estimating cost to obtain from TX DCS program. | C24: Respondents shall comprehensively list the infrastructure requirements for DCS infrastructure within the State Data Center for financial review by the Department. If proposing a DCS-hosted Solution, the Department will use the cost estimating tools available within the program to estimate the cost to host the Solution within the DCS program. Refer to RFO Section C.1.7.3 for DCS requirements.
A25: Optional Services
A26: 7. Optional Services | B26: Propose services or Solution modules that are beyond what is requested in the RFO | C26: Respondents can propose services or Solution modules that are beyond what is requested in the RFO. This Tab is informational only and not part of the cost evaluation.
A27: Rate Sheet
A28: 8. Rate Sheet | B28: Information on roles and rates for staff that may provide additional professional services beyond contract responsibilities | C28: Respondents can specify the roles and rates for staff who may provide additional professional services in the future, beyond the contract responsibilities (e.g., change requests/orders). This Tab is informational only and not part of the cost evaluation.
A29: Assumptions
A30: 9. Assumptions | B30: Itemization of all assumptions upon which price is dependent | C30: Costs of any additional items or services, not specifically delineated in this RFO, must also be reflected in Tab 9. Assumptions of the Cost Workbook. Assumptions used by the Respondent in preparing the Cost Workbook must also be identified and included with the Response.
A32: Note: | B32: All editable cells in this worksheet are highlighted in light yellow.
A33: 1 | B33: The Department will not be billed separately for travel costs. Price shall incorporate any travel and lodging considerations necessary for the successful completion of the project.
A34: 2 | B34: Allowable Costs: The Response shall include only costs that are reasonable, necessary, and allowable under State Statutes, Department Policy, and Federal Cost Standards. The Department shall make the final decision on the allowance or acceptability of costs.
A35: 3 | B35: Non-Allowable Costs: The Response shall not include costs that are not allowed by the State or any authorized agency, statute, policy, or procedure. Types of non-allowable costs may include, but are not limited to, alcoholic beverages, bad debts, fundraising, political lobbying, and tobacco products.

Sheet 2. Total Price Summary
A1: TOC & Instructions
A3: Solicitation Number: | B3: ='0. Cover Sheet'!B7 -> 696-IT-25-O053
A4: Solicitation Name/Title: | B4: ='0. Cover Sheet'!B8 -> Texas Department of Criminal Justice Corrections Information Technology System 2.0 (CITS 2.0)
A5: Respondent Name: | B5: ='0. Cover Sheet'!B9 -> Respondent Name
A7: Total Price Summary
A8: All-Inclusive Deliverable Price ($)
A10: Deliverable Costs | B10: ='3. Deliverables Costs'!F46 -> 0
A11: Total Deliverable Cost for Contract Term | B11: =B10 -> 0
A12: Recurring Costs
B13: Year 1 (12 Months) | C13: Year 2 (12 Months) | D13: Year 3 (12 Months) | E13: Year 4 (12 Months)
A14: License/Subscription Costs | B14: ='4. License Subscription Costs'!E16 -> 0 | C14: ='4. License Subscription Costs'!E17 -> 0 | D14: ='4. License Subscription Costs'!E18 -> 0 | E14: ='4. License Subscription Costs'!E19 -> 0
A15: Maintenance and Support Costs | B15: ='5. Maint. & Operations Costs'!G16 -> 0 | C15: ='5. Maint. & Operations Costs'!G17 -> 0 | D15: ='5. Maint. & Operations Costs'!G18 -> 0 | E15: ='5. Maint. & Operations Costs'!G19 -> 0
A16: Total Recurring Costs Per Year | B16: =SUM(B14:B15) -> 0 | C16: =SUM(C14:C15) -> 0 | D16: =SUM(D14:D15) -> 0 | E16: =SUM(E14:E15) -> 0
A17: Total Recurring Costs for Contract Term | B17: =SUM(B16:E16) -> 0
A18: Total Costs
A19: Total Costs for Contract Term | B19: =B17+B11 -> 0

Sheet 3. Deliverables Costs
A1: TOC & Instructions | D1: ='0. Cover Sheet'!B5 -> EXHIBIT J.6 - Cost Workbook
C3: Solicitation Number: | D3: ='0. Cover Sheet'!B7 -> 696-IT-25-O053
C4: Solicitation Name/Title: | D4: ='0. Cover Sheet'!B8 -> Texas Department of Criminal Justice Corrections Information Technology System 2.0 (CITS 2.0)
C5: Respondent Name: | D5: ='0. Cover Sheet'!B9 -> Respondent Name
A7: INSTRUCTIONS:
A8: 1 | B8: Column A (DEL ID) provides traceability to the related requirement in the Service Requirements (Exhibit J.3).
A9: 2 | B9: Respondent provides their proposed All-Inclusive Deliverable Price(s) in column F in the "yellow" highlighted cells. Other cells are automatically imported or calculated as appropriate.
A10: 3 | B10: Total Period Costs (green cells) are automatically calculated.
A11: 4 | B11: If the Respondent proposes a phased release of CITS (e.g., Custody then Community, or vice versa), the Respondent is required to submit distinct deliverables for each Go-Live Solution increment. EXAMPLE: If Solution is a phased release, then 'DEL-12a Data Conversion and Migration Plan' would be submitted for the first phase Go-Live and 'DEL-12b Data Conversion and Migration Plan' for the next phase. If the Respondent proposes a phased release, insert an additional line item and rename Column A 'Del ID' with 'a', 'b', 'c', etc., (EXAMPLE: DEL-12a, DEL-12b) to indicate the distinct deliverable post Go-Live. Refer to RFO Section C.1.4, Department Preferred Implementation Approach, for more information.
A12: 5 | B12: The Respondent's proposed All-Inclusive Unit Price(s) is for the Services as specified in this Solicitation and shall include all labor, materials, tools, supplies, equipment, and personnel, including but not limited to, travel expenses, associated costs and incidental costs necessary to provide the products and Services according to the minimum specifications, requirements, provisions, terms, and conditions set forth in the Solicitation.
A13: 6 | B13: Respondent MUST provide All-Inclusive Unit Price(s) for a minimum order quantity of one unit. Failure to submit any mandatory requirement with the cost proposal may be grounds for deeming the proposal non-responsive and may disqualify the proposal.
A15: Deliverable Costs
A16: DEL ID | B16: Deliverable | C16: Target Deliverable Submission | D16: Service Domain | E16: Frequency of Delivery (See RFO Section C.1.4 for Department Preferred Implementation Approach) | F16: All-Inclusive Unit Price ($)
A17: DEL-1 | B17: Project Management Plan (PMP) | C17: Within 30 Working Days of the Service Commencement Date | D17: 1. Project and Security Management | E17: Once, and maintained updated throughout Contract Term | F17: 0
A18: DEL-2 | B18: Project Workplan | C18: Within 30 Working Days of the Service Commencement Date | D18: 1. Project and Security Management | E18: Once, and maintained updated throughout Contract Term | F18: 0
A19: DEL-3 | B19: Monthly Performance Reports | C19: As agreed upon in the approved Project Management Plan (PMP) and approved Project Workplan | D19: 1. Project and Security Management | E19: Monthly, throughout the Contract Term | F19: 0
A20: DEL-4 | B20: System Security Plan (SSP) | C20: As agreed upon in the approved Project Workplan deliverable | D20: 1. Project and Security Management | E20: Once, and maintained updated throughout Contract Term | F20: 0
A21: DEL-5 | B21: Requirements Validation and Fit/Gap Report | C21: Within three months of the Service Commencement Date | D21: 2. Requirements Management | E21: Once, and maintained updated throughout Contract Term | F21: 0
A22: DEL-6 | B22: System Design Document | C22: As agreed upon in the approved Project Workplan deliverable | D22: 3. Solution Design and Configuration | E22: Distinct deliverables for the scope of each Go-Live event. | F22: 0
A23: DEL-7 | B23: Sentence Calculation Design Description | C23: As agreed upon in the approved Project Workplan deliverable | D23: 3. Solution Design and Configuration | E23: Distinct deliverables for the scope of each Go-Live event. | F23: 0
A24: DEL-8 | B24: Configuration Management Plan | C24: Within three months of the Service Commencement Date | D24: 3. Solution Design and Configuration | E24: Once, and maintained updated throughout Contract Term | F24: 0
A25: DEL-9 | B25: Commercial Software Licenses and Technical Documentation | C25: Within 30 Days from the initial production implementation of a Solution component. | D25: 3. Solution Design and Configuration | E25: Once, and maintained updated throughout Contract Term | F25: 0
A26: DEL-10 | B26: Interface Control Documents (ICDs) | C26: As agreed upon in the approved Project Workplan deliverable | D26: 4. Integration Services | E26: Delivered once for each Go-Live Solution increment and covering all interfaces within the scope of the Solution components to be placed into production. | F26: 0
A27: DEL-11 | B27: Interfaces Implementation Report | C27: As agreed upon in the approved Project Workplan deliverable | D27: 4. Integration Services | E27: Delivered once for each Go-Live Solution increment and covering all interfaces within the scope of the Solution components to be placed into production. | F27: 0
A28: DEL-12 | B28: Data Conversion and Migration Plan | C28: As agreed upon in the approved Project Workplan deliverable | D28: 5. Data Migration | E28: Delivered once for each Go-Live Solution increment and covering all data within the scope of the Solution components to be placed into production. | F28: 0
... A45: DEL-28 | B45: Final Acceptance Document | C45: Prior to Contract expiration. | D45: 11. Exit Transition | E45: Once | F45: 0
A46: Total Deliverables Costs | F46: =SUM(F17:F45) -> 0

Sheet 4. License Subscription Costs
A1: TOC & Instructions | D1: ='0. Cover Sheet'!B5 -> EXHIBIT J.6 - Cost Workbook
A3: Solicitation Number: | D3: ='0. Cover Sheet'!B7 -> 696-IT-25-O053
A4: Solicitation Name/Title: | D4: ='0. Cover Sheet'!B8 -> Texas Department of Criminal Justice Corrections Information Technology System 2.0 (CITS 2.0)
A5: Respondent Name: | D5: ='0. Cover Sheet'!B9 -> Respondent Name
A7: INSTRUCTIONS:
A8: 1 | B8: Respondent provides their proposed All-Inclusive Deliverable Price(s) in column E in the "yellow" highlighted cells. Other cells are automatically imported or calculated as appropriate.
A9: 2 | B9: Monthly Cost (green cells) are automatically calculated. Green cells under Number of Users are the estimated number of users for that Contract Year.
A10: 3 | B10: Respondents must populate the months in which license subscription costs apply. Licensing subscription costs are only paid by the Department after the Solution is in production.
A11: 4 | B11: The Respondent's proposed Per User Per Month Subscription Costs is the all-inclusive rate for Solution License/Subscription Costs. All recurring costs for the Services as specified in this Solicitation must be included in either this tab or Tab 5. Maint. and Operations Costs, and shall include all labor, materials, tools, supplies, equipment, and personnel, including but not limited to, travel expenses, associated costs and incidental costs necessary to provide the products and Services according to the minimum specifications, requirements, provisions, terms, and conditions set forth in the Solicitation. No additional and/or unlisted recurring costs outside of this or Tab 5. Maint. and Operations Costs will be accepted. Any such costs will be incurred by the Respondent.
A12: 5 | B12: Estimated number of users for the life of the Contract is up to 8,000 concurrent users (20,000 non-concurrent users) as detailed in Section C.3.2.3 - Commercial Software Licensing of the RFO. In the event of any increase of scale of the volume of users through the Contract period, the Respondent will be held to the rates provided in the table above and compensated based on actual number of users per month.
A14: Volume Costs
A15: Contract Year | B15: Quantity (# of Months) | C15: Number of Users | D15: Per User Per Month License Subscription Costs ($) | E15: Total Cost ($)
A16: Year 1 | B16: 0 | C16: 20000 | D16: 0 | E16: =B16*C16*D16 -> 0
A17: Year 2 | B17: 0 | C17: 20000 | D17: 0 | E17: =B17*C17*D17 -> 0
A18: Year 3 | B18: 0 | C18: 20000 | D18: 0 | E18: =B18*C18*D18 -> 0
A19: Year 4 | B19: 0 | C19: 20000 | D19: 0 | E19: =B19*C19*D19 -> 0

Sheet 5.  Maint. & Operations Costs
A1: TOC & Instructions | C1: ='0. Cover Sheet'!B5 -> EXHIBIT J.6 - Cost Workbook
A3: Solicitation Number: | C3: ='0. Cover Sheet'!B7 -> 696-IT-25-O053
A4: Solicitation Name/Title: | C4: ='0. Cover Sheet'!B8 -> Texas Department of Criminal Justice Corrections Information Technology System 2.0 (CITS 2.0)
A5: Respondent Name: | C5: ='0. Cover Sheet'!B9 -> Respondent Name
A7: INSTRUCTIONS:
A8: 1 | B8: The Maintenance and Support costs must align with the proposed workplan. Refer to RFO Section L.8.4 and Exhibit J.5 - Response Template for more information on the required workplan to be submitted with Responses.
A9: 2 | B9: Column C 'Quantity (# of Months)' must correspond with the workplan and only apply to the number of months where Maintenance and Support will take effect.
A10: 3 | B10: Respondent must provide proposed All-Inclusive Service Price(s) in column E in the "yellow" highlighted cells. Other cells are automatically imported or calculated as appropriate.
A11: 4 | B11: Total Period Costs (green cells) are automatically calculated.
A12: 5 | B12: The Respondent's proposed All-Inclusive Service Price(s) is for the Services as specified in this Solicitation. All recurring costs for the Services as specified in this Solicitation must be included in either this tab or Tab 5. Maint. and Operations Costs, and shall include all labor, materials, tools, supplies, equipment, and personnel, including but not limited to, travel expenses, associated costs and incidental costs necessary to provide the products and Services according to the minimum specifications, requirements, provisions, terms, and conditions set forth in the Solicitation. No additional and/or unlisted recurring costs outside of this or Tab 5. Maint. and Operations Costs will be accepted. Any such costs will be incurred by the Respondent.
A14: Maintenance and Support
A15: Contract Year | B15: Description | C15: Quantity (# of Months) | D15: Unit of Measurement (UOM) | E15: All-Inclusive Service Price ($) | G15: Total Cost ($)
A16: Year 1 | B16: Maintenance and Support | C16: 0 | D16: Monthly Fee | E16: 0 | F16: $/Per Month | G16: =C16*E16 -> 0
A17: Year 2 | B17: Maintenance and Support | C17: 0 | D17: Monthly Fee | E17: 0 | F17: $/Per Month | G17: =C17*E17 -> 0
A18: Year 3 | B18: Maintenance and Support | C18: 0 | D18: Monthly Fee | E18: 0 | F18: $/Per Month | G18: =C18*E18 -> 0
A19: Year 4 | B19: Maintenance and Support | C19: 0 | D19: Monthly Fee | E19: 0 | F19: $/Per Month | G19: =C19*E19 -> 0
A20: Total Maintenance and Operations Cost: | G20: =SUM(G16:G19) -> 0

Sheet 6. Infrastructure
A1: TOC & Instructions | C1: ='0. Cover Sheet'!B5 -> EXHIBIT J.6 - Cost Workbook
A3: Solicitation Number: | C3: ='0. Cover Sheet'!B7 -> 696-IT-25-O053
A4: Solicitation Name/Title: | C4: ='0. Cover Sheet'!B8 -> Texas Department of Criminal Justice Corrections Information Technology System 2.0 (CITS 2.0)
A5: Respondent Name: | C5: ='0. Cover Sheet'!B9 -> Respondent Name
A7: INSTRUCTIONS:
A8: 1 | B8: List infrastructure requirements and needs to support the Response. Insert as many lines as necessary to ensure all requirements are expressed.
A9: 2 | B9: All Solutions offered in response to this RFO must leverage the Texas DCS (Data Center Services) infrastructure and services. Refer to RFO Exhibit J.8, Texas Data Center Services, for more information.
A10: 3 | B10: If you are proposing a DCS-hosted Solution, do not provide any costs as the Department will obtain pricing from the DCS program based on the infrastructure and/or computing information provided. Refer to RFO Section C.1.7.3 for DCS Infrastructure Requirements.
B12: Software
A13: 1
A14: 2
A15: 3
A16: 4
A17: 5
A18: 6
A19: 7
A20: 8
A21: 9
A22: 10
A23: 11
A24: 12
B25: Hardware
A26: 1
A27: 2
A28: 3
A29: 4
A30: 5
A31: 6
A32: 7
A33: 8
A34: 9
A35: 10
A36: 11
A37: 12
B38: Tools
A39: 1
A40: 2
A41: 3
A42: 4
A43: 5
...

Sheet 7. Optional Services
A1: TOC & Instructions | B1: ='0. Cover Sheet'!B5 -> EXHIBIT J.6 - Cost Workbook
A3: Solicitation Number: | B3: ='0. Cover Sheet'!B7 -> 696-IT-25-O053
A4: Solicitation Name/Title: | B4: ='0. Cover Sheet'!B8 -> Texas Department of Criminal Justice Corrections Information Technology System 2.0 (CITS 2.0)
A5: Respondent Name: | B5: ='0. Cover Sheet'!B9 -> Respondent Name
A7: INSTRUCTIONS:
A8: 1 | B8: This is for Respondents to propose services or Solution modules that are beyond what is requested in the RFO. This Tab is informational only and not part of the cost evaluation.
A10: # | B10: Optional Service | C10: Description | D10: Costs ($)
A11: 1
A12: 2
A13: 3
A14: 4
A15: 5
A16: 6
A17: 7
A18: 8
A19: 9
A20: 10
A21: 11
A22: 12
... A40: 30

Sheet 8. Rate Sheet
A1: TOC & Instructions | B1: ='0. Cover Sheet'!B5 -> EXHIBIT J.6 - Cost Workbook
A3: Solicitation Number: | B3: ='0. Cover Sheet'!B7 -> 696-IT-25-O053
A4: Solicitation Name/Title: | B4: ='0. Cover Sheet'!B8 -> Texas Department of Criminal Justice Corrections Information Technology System 2.0 (CITS 2.0)
A5: Respondent Name: | B5: ='0. Cover Sheet'!B9 -> Respondent Name
A7: INSTRUCTIONS:
A8: 1 | B8: This is for Respondents to specify the roles and rates for staff who may provide additional professional services in the future, beyond the contract responsibilities (e.g., change requests/orders). This Tab is informational only and not part of the cost evaluation.
A10: # | B10: Role | C10: Hourly Rate ($) (Applicable to the contract period of performance)
A11: 1
A12: 2
A13: 3
A14: 4
A15: 5
A16: 6
A17: 7
A18: 8
A19: 9
A20: 10
A21: 11
A22: 12
... A40: 30

Sheet 9. Assumptions
A1: TOC & Instructions | D1: ='0. Cover Sheet'!B5 -> EXHIBIT J.6 - Cost Workbook
A3: Solicitation Number: | D3: ='0. Cover Sheet'!B7 -> 696-IT-25-O053
A4: Solicitation Name/Title: | D4: ='0. Cover Sheet'!B8 -> Texas Department of Criminal Justice Corrections Information Technology System 2.0 (CITS 2.0)
A5: Respondent Name: | D5: ='0. Cover Sheet'!B9 -> Respondent Name
A7: INSTRUCTIONS:
A8: 1 | B8: List assumptions upon which costs are determined. Only assumptions that impact the pricing should be listed in this Tab. All other assumptions must be listed in the Response (See Exhibit J.5 Response Template) Insert as many lines as necessary to ensure all assumptions are accurately expressed. Please note that Respondents should submit questions by the specified deadline in order to resolve assumptions. This tab is for any remaining assumptions that were not resolved. Refer to RFO Section L.1. for more instructions on submitting questions and how the answers will be published.
A9: 2 | B9: For Cost Implications, provide an explanation of the cost impacts (e.g., increased cost, decreased cost) and an estimated dollar amount (or range) for the anticipated cost impact.
A11: # | B11: Category | C11: Assumptions | F11: Cost Implications
A12: 1
A13: 2
A14: 3
A15: 4
A16: 5
A17: 6
A18: 7
A19: 8
A20: 9
A21: 10
A22: 11
A23: 12
... A41: 30

Sheet Sheet3
A1: 1. Project and Security Management
A2: 2. Requirements Management
A3: 3. Solution Design and Configuration
A4: 4. Integration Services
A5: 5. Data Migration
A6: 6. Solution Testing
A7: 7. User Training
A8: 8. Hosting and solution provisioning
A9: 9. Cutover/Deployment/Hypercare
A10: 10. Maintenance and Operations
A11: 11. Exit Transition Out/Turnover
